Workbook

Sheet Sales Detail
A1: To be completed by Sales / Client - Request for proposal
A2: Name of Sales Lead
A3: General information
A4: Client/prospect name (e.g. UNICEF)
A5: Estimate name (Design & Development of unicef.org)
A6: Date raised (MMM/DD/YYYY)
A7: Final Date for Questions
A8: Estimate deadline
A9: Project deadline with reason (if any):
A10: Estimated budget range (e.g. $ 50K, CAD 50K, INR 100K)
A11: Estimate Complexity | B11: Simple
A12: Requirements
A13: Type of Estimate | B13: Custom (Scratch)
A14: Summary of requirements
A15: Key content areas of the website
A16: Current platform details
A17: Target audience
A18: Sitemap (if available)
A19: Total number of pages
A20: Total number of components (e.g. Simple - 10, Medium - 10, Complex - 5)
A21: Total number of templates
A22: Total number of Press Releases
A23: Total number of document uploads
A24: Total number of video uploads
A25: Number of languages (Please also specify the lang. versions)
... A28: Infrastructure Architecture
A29: Probability of sign-off | B29: 0.5
A30: Priority | B30: P1
A31: Reason for Priority

Sheet Questions for RFP
A1: Q&A Submission deadline
A2: Sr. No | B2: Topic | C2: TOR Reference | D2: Questions | E2: Impact on Estimates based on possibilities | F2: Additional Comments (if any)

Sheet Submission timelines
B1: Estimate Kick Off | C1: 45013 | G1: =G2 -> 45012 | N1: =N2 -> 45019 | Q1: =Q2 -> 45022 | U1: =U2 -> 45026 | AB1: =AB2 -> 45033 | AI1: =AI2 -> 45040 | AP1: =AP2 -> 45047
A2: Task ID | B2: Task details | C2: Task Duration (days) | D2: Start Date | E2: End Date | F2: Milestone | G2: =C1-WEEKDAY(C1,3) -> 45012 | H2: =G2+1 -> 45013 | I2: =H2+1 -> 45014 | J2: =I2+1 -> 45015 | K2: =J2+1 -> 45016 | L2: =K2+1 -> 45017 | M2: =L2+1 -> 45018 | N2: =M2+1 -> 45019 | O2: =N2+1 -> 45020 | ... AV2: =AU2+1 -> 45053
G3: =LEFT(TEXT(IF(WEEKDAY(G2,2)>5,"S",WEEKDAY(G2)),"ddd"),1) -> M | H3: =LEFT(TEXT(IF(WEEKDAY(H2,2)>5,"S",WEEKDAY(H2)),"ddd"),1) -> T | I3: =LEFT(TEXT(IF(WEEKDAY(I2,2)>5,"S",WEEKDAY(I2)),"ddd"),1) -> W | J3: =LEFT(TEXT(IF(WEEKDAY(J2,2)>5,"S",WEEKDAY(J2)),"ddd"),1) -> T | K3: =LEFT(TEXT(IF(WEEKDAY(K2,2)>5,"S",WEEKDAY(K2)),"ddd"),1) -> F | L3: =LEFT(TEXT(IF(WEEKDAY(L2,2)>5,"S",WEEKDAY(L2)),"ddd"),1) -> S | M3: =LEFT(TEXT(IF(WEEKDAY(M2,2)>5,"S",WEEKDAY(M2)),"ddd"),1) -> S | N3: =LEFT(TEXT(IF(WEEKDAY(N2,2)>5,"S",WEEKDAY(N2)),"ddd"),1) -> M | ... AV3: =LEFT(TEXT(IF(WEEKDAY(AV2,2)>5,"S",WEEKDAY(AV2)),"ddd"),1) -> S
A4: 1 | B4: De-briefing call with the team | C4: 1 | D4: =C1 -> 45013 | E4: =_xlfn.WORKDAY.INTL(D4,0,1) -> 45013 | F4: No | G4: =IF(AND($F4="Yes",G$2=$E4),"♦","") | H4: =IF(AND($F4="Yes",H$2=$E4),"♦","") | I4: =IF(AND($F4="Yes",I$2=$E4),"♦","") | J4: =IF(AND($F4="Yes",J$2=$E4),"♦","") | K4: =IF(AND($F4="Yes",K$2=$E4),"♦","") | L4: =IF(AND($F4="Yes",L$2=$E4),"♦","") | M4: =IF(AND($F4="Yes",M$2=$E4),"♦","") | N4: =IF(AND($F4="Yes",N$2=$E4),"♦","") | ... AV4: =IF(AND($F4="Yes",AV$2=$E4),"♦","")
A5: 2 | B5: Review scope and Estimate hours | C5: 5 | D5: =_xlfn.WORKDAY.INTL(E4,0,1) -> 45013 | E5: =_xlfn.WORKDAY.INTL(D5,C5,1) -> 45020 | F5: No | G5: =IF(AND($F5="Yes",G$2=$E5),"♦","") | H5: =IF(AND($F5="Yes",H$2=$E5),"♦","") | I5: =IF(AND($F5="Yes",I$2=$E5),"♦","") | J5: =IF(AND($F5="Yes",J$2=$E5),"♦","") | K5: =IF(AND($F5="Yes",K$2=$E5),"♦","") | L5: =IF(AND($F5="Yes",L$2=$E5),"♦","") | M5: =IF(AND($F5="Yes",M$2=$E5),"♦","") | N5: =IF(AND($F5="Yes",N$2=$E5),"♦","") | ... AV5: =IF(AND($F5="Yes",AV$2=$E5),"♦","")
A6: 4 | B6: Preparing proposal response | C6: 6 | D6: =_xlfn.WORKDAY.INTL(D4,0,1) -> 45013 | E6: =_xlfn.WORKDAY.INTL(D6,C6-1,1) -> 45020 | F6: No | G6: =IF(AND($F6="Yes",G$2=$E6),"♦","") | H6: =IF(AND($F6="Yes",H$2=$E6),"♦","") | I6: =IF(AND($F6="Yes",I$2=$E6),"♦","") | J6: =IF(AND($F6="Yes",J$2=$E6),"♦","") | K6: =IF(AND($F6="Yes",K$2=$E6),"♦","") | L6: =IF(AND($F6="Yes",L$2=$E6),"♦","") | M6: =IF(AND($F6="Yes",M$2=$E6),"♦","") | N6: =IF(AND($F6="Yes",N$2=$E6),"♦","") | ... AV6: =IF(AND($F6="Yes",AV$2=$E6),"♦","")
A7: 5 | B7: Internal review of proposal & Updates | C7: 2 | D7: =_xlfn.WORKDAY.INTL(E6,1,1) -> 45021 | E7: =_xlfn.WORKDAY.INTL(D7,C7-1,1) -> 45022 | F7: No | G7: =IF(AND($F7="Yes",G$2=$E7),"♦","") | H7: =IF(AND($F7="Yes",H$2=$E7),"♦","") | I7: =IF(AND($F7="Yes",I$2=$E7),"♦","") | J7: =IF(AND($F7="Yes",J$2=$E7),"♦","") | K7: =IF(AND($F7="Yes",K$2=$E7),"♦","") | L7: =IF(AND($F7="Yes",L$2=$E7),"♦","") | M7: =IF(AND($F7="Yes",M$2=$E7),"♦","") | N7: =IF(AND($F7="Yes",N$2=$E7),"♦","") | ... AV7: =IF(AND($F7="Yes",AV$2=$E7),"♦","")
A8: 6 | B8: Internal sign off & Submission | C8: 0 | D8: =_xlfn.WORKDAY.INTL(E7,1,1) -> 45023 | E8: =_xlfn.WORKDAY.INTL(D8,C8,1) -> 45023 | F8: Yes | G8: =IF(AND($F8="Yes",G$2=$E8),"♦","") | H8: =IF(AND($F8="Yes",H$2=$E8),"♦","") | I8: =IF(AND($F8="Yes",I$2=$E8),"♦","") | J8: =IF(AND($F8="Yes",J$2=$E8),"♦","") | K8: =IF(AND($F8="Yes",K$2=$E8),"♦","") | L8: =IF(AND($F8="Yes",L$2=$E8),"♦","") | M8: =IF(AND($F8="Yes",M$2=$E8),"♦","") | N8: =IF(AND($F8="Yes",N$2=$E8),"♦","") | ... AV8: =IF(AND($F8="Yes",AV$2=$E8),"♦","")
A9: 8 | B9: 7 April 2023 at 5:00 P.M. (CET, Paris time) via email to Emilie.Sutton@oecd.org, EDU.Contracts@oecd.org and globalteachinginsights@oecd.org. | G9: =IF(AND($F9="Yes",G$2=$E9),"♦","") | H9: =IF(AND($F9="Yes",H$2=$E9),"♦","") | I9: =IF(AND($F9="Yes",I$2=$E9),"♦","") | J9: =IF(AND($F9="Yes",J$2=$E9),"♦","") | K9: =IF(AND($F9="Yes",K$2=$E9),"♦","") | L9: =IF(AND($F9="Yes",L$2=$E9),"♦","") | M9: =IF(AND($F9="Yes",M$2=$E9),"♦","") | N9: =IF(AND($F9="Yes",N$2=$E9),"♦","") | ... AV9: =IF(AND($F9="Yes",AV$2=$E9),"♦","")
A10: 9 | G10: =IF(AND($F10="Yes",G$2=$E10),"♦","") | H10: =IF(AND($F10="Yes",H$2=$E10),"♦","") | I10: =IF(AND($F10="Yes",I$2=$E10),"♦","") | J10: =IF(AND($F10="Yes",J$2=$E10),"♦","") | K10: =IF(AND($F10="Yes",K$2=$E10),"♦","") | L10: =IF(AND($F10="Yes",L$2=$E10),"♦","") | M10: =IF(AND($F10="Yes",M$2=$E10),"♦","") | N10: =IF(AND($F10="Yes",N$2=$E10),"♦","") | ... AV10: =IF(AND($F10="Yes",AV$2=$E10),"♦","")
A11: 10 | G11: =IF(AND($F11="Yes",G$2=$E11),"♦","") | H11: =IF(AND($F11="Yes",H$2=$E11),"♦","") | I11: =IF(AND($F11="Yes",I$2=$E11),"♦","") | J11: =IF(AND($F11="Yes",J$2=$E11),"♦","") | K11: =IF(AND($F11="Yes",K$2=$E11),"♦","") | L11: =IF(AND($F11="Yes",L$2=$E11),"♦","") | M11: =IF(AND($F11="Yes",M$2=$E11),"♦","") | N11: =IF(AND($F11="Yes",N$2=$E11),"♦","") | ... AV11: =IF(AND($F11="Yes",AV$2=$E11),"♦","")
A12: 11 | G12: =IF(AND($F12="Yes",G$2=$E12),"♦","") | H12: =IF(AND($F12="Yes",H$2=$E12),"♦","") | I12: =IF(AND($F12="Yes",I$2=$E12),"♦","") | J12: =IF(AND($F12="Yes",J$2=$E12),"♦","") | K12: =IF(AND($F12="Yes",K$2=$E12),"♦","") | L12: =IF(AND($F12="Yes",L$2=$E12),"♦","") | M12: =IF(AND($F12="Yes",M$2=$E12),"♦","") | N12: =IF(AND($F12="Yes",N$2=$E12),"♦","") | ... AV12: =IF(AND($F12="Yes",AV$2=$E12),"♦","")
A13: 12 | G13: =IF(AND($F13="Yes",G$2=$E13),"♦","") | H13: =IF(AND($F13="Yes",H$2=$E13),"♦","") | I13: =IF(AND($F13="Yes",I$2=$E13),"♦","") | J13: =IF(AND($F13="Yes",J$2=$E13),"♦","") | K13: =IF(AND($F13="Yes",K$2=$E13),"♦","") | L13: =IF(AND($F13="Yes",L$2=$E13),"♦","") | M13: =IF(AND($F13="Yes",M$2=$E13),"♦","") | N13: =IF(AND($F13="Yes",N$2=$E13),"♦","") | ... AV13: =IF(AND($F13="Yes",AV$2=$E13),"♦","")
A14: 13 | G14: =IF(AND($F14="Yes",G$2=$E14),"♦","") | H14: =IF(AND($F14="Yes",H$2=$E14),"♦","") | I14: =IF(AND($F14="Yes",I$2=$E14),"♦","") | J14: =IF(AND($F14="Yes",J$2=$E14),"♦","") | K14: =IF(AND($F14="Yes",K$2=$E14),"♦","") | L14: =IF(AND($F14="Yes",L$2=$E14),"♦","") | M14: =IF(AND($F14="Yes",M$2=$E14),"♦","") | N14: =IF(AND($F14="Yes",N$2=$E14),"♦","") | ... AV14: =IF(AND($F14="Yes",AV$2=$E14),"♦","")
A15: 14 | G15: =IF(AND($F15="Yes",G$2=$E15),"♦","") | H15: =IF(AND($F15="Yes",H$2=$E15),"♦","") | I15: =IF(AND($F15="Yes",I$2=$E15),"♦","") | J15: =IF(AND($F15="Yes",J$2=$E15),"♦","") | K15: =IF(AND($F15="Yes",K$2=$E15),"♦","") | L15: =IF(AND($F15="Yes",L$2=$E15),"♦","") | M15: =IF(AND($F15="Yes",M$2=$E15),"♦","") | N15: =IF(AND($F15="Yes",N$2=$E15),"♦","") | ... AV15: =IF(AND($F15="Yes",AV$2=$E15),"♦","")
A16: 15 | G16: =IF(AND($F16="Yes",G$2=$E16),"♦","") | H16: =IF(AND($F16="Yes",H$2=$E16),"♦","") | I16: =IF(AND($F16="Yes",I$2=$E16),"♦","") | J16: =IF(AND($F16="Yes",J$2=$E16),"♦","") | K16: =IF(AND($F16="Yes",K$2=$E16),"♦","") | L16: =IF(AND($F16="Yes",L$2=$E16),"♦","") | M16: =IF(AND($F16="Yes",M$2=$E16),"♦","") | N16: =IF(AND($F16="Yes",N$2=$E16),"♦","") | ... AV16: =IF(AND($F16="Yes",AV$2=$E16),"♦","")
A17: 16 | G17: =IF(AND($F17="Yes",G$2=$E17),"♦","") | H17: =IF(AND($F17="Yes",H$2=$E17),"♦","") | I17: =IF(AND($F17="Yes",I$2=$E17),"♦","") | J17: =IF(AND($F17="Yes",J$2=$E17),"♦","") | K17: =IF(AND($F17="Yes",K$2=$E17),"♦","") | L17: =IF(AND($F17="Yes",L$2=$E17),"♦","") | M17: =IF(AND($F17="Yes",M$2=$E17),"♦","") | N17: =IF(AND($F17="Yes",N$2=$E17),"♦","") | ... AV17: =IF(AND($F17="Yes",AV$2=$E17),"♦","")
A18: 17 | G18: =IF(AND($F18="Yes",G$2=$E18),"♦","") | H18: =IF(AND($F18="Yes",H$2=$E18),"♦","") | I18: =IF(AND($F18="Yes",I$2=$E18),"♦","") | J18: =IF(AND($F18="Yes",J$2=$E18),"♦","") | K18: =IF(AND($F18="Yes",K$2=$E18),"♦","") | L18: =IF(AND($F18="Yes",L$2=$E18),"♦","") | M18: =IF(AND($F18="Yes",M$2=$E18),"♦","") | N18: =IF(AND($F18="Yes",N$2=$E18),"♦","") | ... AV18: =IF(AND($F18="Yes",AV$2=$E18),"♦","")
A19: 18 | G19: =IF(AND($F19="Yes",G$2=$E19),"♦","") | H19: =IF(AND($F19="Yes",H$2=$E19),"♦","") | I19: =IF(AND($F19="Yes",I$2=$E19),"♦","") | J19: =IF(AND($F19="Yes",J$2=$E19),"♦","") | K19: =IF(AND($F19="Yes",K$2=$E19),"♦","") | L19: =IF(AND($F19="Yes",L$2=$E19),"♦","") | M19: =IF(AND($F19="Yes",M$2=$E19),"♦","") | N19: =IF(AND($F19="Yes",N$2=$E19),"♦","") | ... AV19: =IF(AND($F19="Yes",AV$2=$E19),"♦","")
A20: 19 | G20: =IF(AND($F20="Yes",G$2=$E20),"♦","") | H20: =IF(AND($F20="Yes",H$2=$E20),"♦","") | I20: =IF(AND($F20="Yes",I$2=$E20),"♦","") | J20: =IF(AND($F20="Yes",J$2=$E20),"♦","") | K20: =IF(AND($F20="Yes",K$2=$E20),"♦","") | L20: =IF(AND($F20="Yes",L$2=$E20),"♦","") | M20: =IF(AND($F20="Yes",M$2=$E20),"♦","") | N20: =IF(AND($F20="Yes",N$2=$E20),"♦","") | ... AV20: =IF(AND($F20="Yes",AV$2=$E20),"♦","")
A21: 20 | G21: =IF(AND($F21="Yes",G$2=$E21),"♦","") | H21: =IF(AND($F21="Yes",H$2=$E21),"♦","") | I21: =IF(AND($F21="Yes",I$2=$E21),"♦","") | J21: =IF(AND($F21="Yes",J$2=$E21),"♦","") | K21: =IF(AND($F21="Yes",K$2=$E21),"♦","") | L21: =IF(AND($F21="Yes",L$2=$E21),"♦","") | M21: =IF(AND($F21="Yes",M$2=$E21),"♦","") | N21: =IF(AND($F21="Yes",N$2=$E21),"♦","") | ... AV21: =IF(AND($F21="Yes",AV$2=$E21),"♦","")
... A98: 97 | G98: =IF(AND($F98="Yes",G$2=$E98),"♦","") | H98: =IF(AND($F98="Yes",H$2=$E98),"♦","") | I98: =IF(AND($F98="Yes",I$2=$E98),"♦","") | J98: =IF(AND($F98="Yes",J$2=$E98),"♦","") | K98: =IF(AND($F98="Yes",K$2=$E98),"♦","") | L98: =IF(AND($F98="Yes",L$2=$E98),"♦","") | M98: =IF(AND($F98="Yes",M$2=$E98),"♦","") | N98: =IF(AND($F98="Yes",N$2=$E98),"♦","") | ... AV98: =IF(AND($F98="Yes",AV$2=$E98),"♦","")
A99: 97

Sheet Discovery
B1: TO BE FILLED IN BY THE PERSON WORKING ON THE ESTIMATE
B2: Name | H2: 0 | I2: Contigency / Confidence level
B3: Date | C3: 45020 | H3: =ROUNDUP(G33*H2,0) -> 0 | I3: Contingency Hours
B4: Total Hours | C4: =ROUNDUP(sum(G33,H3),0) -> 0 | L4: Total AI Efficacy Hours | M4: =ROUNDUP(SUM(N33,H3),0) -> 0
B5: VERIFIED BY
B6: Task | C6: Description | D6: AI Efficacy | E6: HOURS | F6: Conf | G6: Low Hrs | H6: High Hrs | I6: Assumptions | J6: Exclusions | K6: Reference links | L6: AI Efficacy HOURS | M6: Conf | N6: Low Hrs | O6: High Hrs
B7: Discovery Workshop | D7: 0 | F7: 6 | G7: {=ROUNDUP(IF(EQ(A7, ""),E7*INDEX(UncertaintyFactors!$C$2:$D$7, F7, 1), 0), 1)} -> 0 | H7: {=ROUNDUP(IF(EQ(A7, ""), E7*INDEX(UncertaintyFactors!$C$2:$D$7, F7, 2), 0), 1)} -> 0 | L7: =E7-(E7*D7) -> 0 | M7: =F7 -> 6 | N7: {=ROUNDUP(IF(EQ(A7, ""),L7*INDEX(UncertaintyFactors!$C$2:$D$7, M7, 1), 0), 1)} -> 0 | O7: {=ROUNDUP(IF(EQ(A7, ""), L7*INDEX(UncertaintyFactors!$C$2:$D$7, M7, 2), 0), 1)} -> 0
B8: Desk/Exploratory Research | D8: 0 | F8: 6 | G8: {=ROUNDUP(IF(EQ(A8, ""),E8*INDEX(UncertaintyFactors!$C$2:$D$7, F8, 1), 0), 1)} -> 0 | H8: {=ROUNDUP(IF(EQ(A8, ""), E8*INDEX(UncertaintyFactors!$C$2:$D$7, F8, 2), 0), 1)} -> 0 | L8: =E8-(E8*D8) -> 0 | M8: =F8 -> 6 | N8: {=ROUNDUP(IF(EQ(A8, ""),L8*INDEX(UncertaintyFactors!$C$2:$D$7, M8, 1), 0), 1)} -> 0 | O8: {=ROUNDUP(IF(EQ(A8, ""), L8*INDEX(UncertaintyFactors!$C$2:$D$7, M8, 2), 0), 1)} -> 0
B9: User/Stakeholders Interviews/ Surveys | D9: 0 | F9: 6 | G9: {=ROUNDUP(IF(EQ(A9, ""),E9*INDEX(UncertaintyFactors!$C$2:$D$7, F9, 1), 0), 1)} -> 0 | H9: {=ROUNDUP(IF(EQ(A9, ""), E9*INDEX(UncertaintyFactors!$C$2:$D$7, F9, 2), 0), 1)} -> 0 | L9: =E9-(E9*D9) -> 0 | M9: =F9 -> 6 | N9: {=ROUNDUP(IF(EQ(A9, ""),L9*INDEX(UncertaintyFactors!$C$2:$D$7, M9, 1), 0), 1)} -> 0 | O9: {=ROUNDUP(IF(EQ(A9, ""), L9*INDEX(UncertaintyFactors!$C$2:$D$7, M9, 2), 0), 1)} -> 0
B10: Competitive Analysis | D10: 0.1 | F10: 6 | G10: {=ROUNDUP(IF(EQ(A10, ""),E10*INDEX(UncertaintyFactors!$C$2:$D$7, F10, 1), 0), 1)} -> 0 | H10: {=ROUNDUP(IF(EQ(A10, ""), E10*INDEX(UncertaintyFactors!$C$2:$D$7, F10, 2), 0), 1)} -> 0 | L10: =E10-(E10*D10) -> 0 | M10: =F10 -> 6 | N10: {=ROUNDUP(IF(EQ(A10, ""),L10*INDEX(UncertaintyFactors!$C$2:$D$7, M10, 1), 0), 1)} -> 0 | O10: {=ROUNDUP(IF(EQ(A10, ""), L10*INDEX(UncertaintyFactors!$C$2:$D$7, M10, 2), 0), 1)} -> 0
B11: Defining User Personas | D11: 0 | F11: 6 | G11: {=ROUNDUP(IF(EQ(A11, ""),E11*INDEX(UncertaintyFactors!$C$2:$D$7, F11, 1), 0), 1)} -> 0 | H11: {=ROUNDUP(IF(EQ(A11, ""), E11*INDEX(UncertaintyFactors!$C$2:$D$7, F11, 2), 0), 1)} -> 0 | L11: =E11-(E11*D11) -> 0 | M11: =F11 -> 6 | N11: {=ROUNDUP(IF(EQ(A11, ""),L11*INDEX(UncertaintyFactors!$C$2:$D$7, M11, 1), 0), 1)} -> 0 | O11: {=ROUNDUP(IF(EQ(A11, ""), L11*INDEX(UncertaintyFactors!$C$2:$D$7, M11, 2), 0), 1)} -> 0
B12: Defining User Journey | D12: 0 | F12: 6 | G12: {=ROUNDUP(IF(EQ(A12, ""),E12*INDEX(UncertaintyFactors!$C$2:$D$7, F12, 1), 0), 1)} -> 0 | H12: {=ROUNDUP(IF(EQ(A12, ""), E12*INDEX(UncertaintyFactors!$C$2:$D$7, F12, 2), 0), 1)} -> 0 | L12: =E12-(E12*D12) -> 0 | M12: =F12 -> 6 | N12: {=ROUNDUP(IF(EQ(A12, ""),L12*INDEX(UncertaintyFactors!$C$2:$D$7, M12, 1), 0), 1)} -> 0 | O12: {=ROUNDUP(IF(EQ(A12, ""), L12*INDEX(UncertaintyFactors!$C$2:$D$7, M12, 2), 0), 1)} -> 0
B13: Foudational Research Report | D13: 0 | F13: 6 | G13: {=ROUNDUP(IF(EQ(A13, ""),E13*INDEX(UncertaintyFactors!$C$2:$D$7, F13, 1), 0), 1)} -> 0 | H13: {=ROUNDUP(IF(EQ(A13, ""), E13*INDEX(UncertaintyFactors!$C$2:$D$7, F13, 2), 0), 1)} -> 0 | L13: =E13-(E13*D13) -> 0 | M13: =F13 -> 6 | N13: {=ROUNDUP(IF(EQ(A13, ""),L13*INDEX(UncertaintyFactors!$C$2:$D$7, M13, 1), 0), 1)} -> 0 | O13: {=ROUNDUP(IF(EQ(A13, ""), L13*INDEX(UncertaintyFactors!$C$2:$D$7, M13, 2), 0), 1)} -> 0
B14: Possible Feature Ideations | D14: 0 | F14: 6 | G14: {=ROUNDUP(IF(EQ(A14, ""),E14*INDEX(UncertaintyFactors!$C$2:$D$7, F14, 1), 0), 1)} -> 0 | H14: {=ROUNDUP(IF(EQ(A14, ""), E14*INDEX(UncertaintyFactors!$C$2:$D$7, F14, 2), 0), 1)} -> 0 | L14: =E14-(E14*D14) -> 0 | M14: =F14 -> 6 | N14: {=ROUNDUP(IF(EQ(A14, ""),L14*INDEX(UncertaintyFactors!$C$2:$D$7, M14, 1), 0), 1)} -> 0 | O14: {=ROUNDUP(IF(EQ(A14, ""), L14*INDEX(UncertaintyFactors!$C$2:$D$7, M14, 2), 0), 1)} -> 0
B15: Understanding globalteachinginsights content source & Planning Migration of videos | D15: 0 | F15: 6 | G15: {=ROUNDUP(IF(EQ(A15, ""),E15*INDEX(UncertaintyFactors!$C$2:$D$7, F15, 1), 0), 1)} -> 0 | H15: {=ROUNDUP(IF(EQ(A15, ""), E15*INDEX(UncertaintyFactors!$C$2:$D$7, F15, 2), 0), 1)} -> 0 | L15: =E15-(E15*D15) -> 0 | M15: =F15 -> 6 | N15: {=ROUNDUP(IF(EQ(A15, ""),L15*INDEX(UncertaintyFactors!$C$2:$D$7, M15, 1), 0), 1)} -> 0 | O15: {=ROUNDUP(IF(EQ(A15, ""), L15*INDEX(UncertaintyFactors!$C$2:$D$7, M15, 2), 0), 1)} -> 0
B16: Planning & Drafting Content Architecture | D16: 0 | F16: 6 | G16: {=ROUNDUP(IF(EQ(A16, ""),E16*INDEX(UncertaintyFactors!$C$2:$D$7, F16, 1), 0), 1)} -> 0 | H16: {=ROUNDUP(IF(EQ(A16, ""), E16*INDEX(UncertaintyFactors!$C$2:$D$7, F16, 2), 0), 1)} -> 0 | L16: =E16-(E16*D16) -> 0 | M16: =F16 -> 6 | N16: {=ROUNDUP(IF(EQ(A16, ""),L16*INDEX(UncertaintyFactors!$C$2:$D$7, M16, 1), 0), 1)} -> 0 | O16: {=ROUNDUP(IF(EQ(A16, ""), L16*INDEX(UncertaintyFactors!$C$2:$D$7, M16, 2), 0), 1)} -> 0
B17: Project communication | D17: 0.05 | F17: 6 | G17: {=ROUNDUP(IF(EQ(A17, ""),E17*INDEX(UncertaintyFactors!$C$2:$D$7, F17, 1), 0), 1)} -> 0 | H17: {=ROUNDUP(IF(EQ(A17, ""), E17*INDEX(UncertaintyFactors!$C$2:$D$7, F17, 2), 0), 1)} -> 0 | L17: =E17-(E17*D17) -> 0 | M17: =F17 -> 6 | N17: {=ROUNDUP(IF(EQ(A17, ""),L17*INDEX(UncertaintyFactors!$C$2:$D$7, M17, 1), 0), 1)} -> 0 | O17: {=ROUNDUP(IF(EQ(A17, ""), L17*INDEX(UncertaintyFactors!$C$2:$D$7, M17, 2), 0), 1)} -> 0
D18: 0 | F18: 6 | G18: {=ROUNDUP(IF(EQ(A18, ""),E18*INDEX(UncertaintyFactors!$C$2:$D$7, F18, 1), 0), 1)} -> 0 | H18: {=ROUNDUP(IF(EQ(A18, ""), E18*INDEX(UncertaintyFactors!$C$2:$D$7, F18, 2), 0), 1)} -> 0 | L18: =E18-(E18*D18) -> 0 | M18: =F18 -> 6 | N18: {=ROUNDUP(IF(EQ(A18, ""),L18*INDEX(UncertaintyFactors!$C$2:$D$7, M18, 1), 0), 1)} -> 0 | O18: {=ROUNDUP(IF(EQ(A18, ""), L18*INDEX(UncertaintyFactors!$C$2:$D$7, M18, 2), 0), 1)} -> 0
D19: 0 | F19: 6 | G19: {=ROUNDUP(IF(EQ(A19, ""),E19*INDEX(UncertaintyFactors!$C$2:$D$7, F19, 1), 0), 1)} -> 0 | H19: {=ROUNDUP(IF(EQ(A19, ""), E19*INDEX(UncertaintyFactors!$C$2:$D$7, F19, 2), 0), 1)} -> 0 | L19: =E19-(E19*D19) -> 0 | M19: =F19 -> 6 | N19: {=ROUNDUP(IF(EQ(A19, ""),L19*INDEX(UncertaintyFactors!$C$2:$D$7, M19, 1), 0), 1)} -> 0 | O19: {=ROUNDUP(IF(EQ(A19, ""), L19*INDEX(UncertaintyFactors!$C$2:$D$7, M19, 2), 0), 1)} -> 0
D20: 0 | F20: 6 | G20: {=ROUNDUP(IF(EQ(A20, ""),E20*INDEX(UncertaintyFactors!$C$2:$D$7, F20, 1), 0), 1)} -> 0 | H20: {=ROUNDUP(IF(EQ(A20, ""), E20*INDEX(UncertaintyFactors!$C$2:$D$7, F20, 2), 0), 1)} -> 0 | L20: =E20-(E20*D20) -> 0 | M20: =F20 -> 6 | N20: {=ROUNDUP(IF(EQ(A20, ""),L20*INDEX(UncertaintyFactors!$C$2:$D$7, M20, 1), 0), 1)} -> 0 | O20: {=ROUNDUP(IF(EQ(A20, ""), L20*INDEX(UncertaintyFactors!$C$2:$D$7, M20, 2), 0), 1)} -> 0
D21: 0 | F21: 6 | G21: {=ROUNDUP(IF(EQ(A21, ""),E21*INDEX(UncertaintyFactors!$C$2:$D$7, F21, 1), 0), 1)} -> 0 | H21: {=ROUNDUP(IF(EQ(A21, ""), E21*INDEX(UncertaintyFactors!$C$2:$D$7, F21, 2), 0), 1)} -> 0 | L21: =E21-(E21*D21) -> 0 | M21: =F21 -> 6 | N21: {=ROUNDUP(IF(EQ(A21, ""),L21*INDEX(UncertaintyFactors!$C$2:$D$7, M21, 1), 0), 1)} -> 0 | O21: {=ROUNDUP(IF(EQ(A21, ""), L21*INDEX(UncertaintyFactors!$C$2:$D$7, M21, 2), 0), 1)} -> 0
D22: 0 | F22: 6 | G22: {=ROUNDUP(IF(EQ(A22, ""),E22*INDEX(UncertaintyFactors!$C$2:$D$7, F22, 1), 0), 1)} -> 0 | H22: {=ROUNDUP(IF(EQ(A22, ""), E22*INDEX(UncertaintyFactors!$C$2:$D$7, F22, 2), 0), 1)} -> 0 | L22: =E22-(E22*D22) -> 0 | M22: =F22 -> 6 | N22: {=ROUNDUP(IF(EQ(A22, ""),L22*INDEX(UncertaintyFactors!$C$2:$D$7, M22, 1), 0), 1)} -> 0 | O22: {=ROUNDUP(IF(EQ(A22, ""), L22*INDEX(UncertaintyFactors!$C$2:$D$7, M22, 2), 0), 1)} -> 0
D23: 0 | F23: 6 | G23: {=ROUNDUP(IF(EQ(A23, ""),E23*INDEX(UncertaintyFactors!$C$2:$D$7, F23, 1), 0), 1)} -> 0 | H23: {=ROUNDUP(IF(EQ(A23, ""), E23*INDEX(UncertaintyFactors!$C$2:$D$7, F23, 2), 0), 1)} -> 0 | L23: =E23-(E23*D23) -> 0 | M23: =F23 -> 6 | N23: {=ROUNDUP(IF(EQ(A23, ""),L23*INDEX(UncertaintyFactors!$C$2:$D$7, M23, 1), 0), 1)} -> 0 | O23: {=ROUNDUP(IF(EQ(A23, ""), L23*INDEX(UncertaintyFactors!$C$2:$D$7, M23, 2), 0), 1)} -> 0
D24: 0 | F24: 6 | G24: {=ROUNDUP(IF(EQ(A24, ""),E24*INDEX(UncertaintyFactors!$C$2:$D$7, F24, 1), 0), 1)} -> 0 | H24: {=ROUNDUP(IF(EQ(A24, ""), E24*INDEX(UncertaintyFactors!$C$2:$D$7, F24, 2), 0), 1)} -> 0 | L24: =E24-(E24*D24) -> 0 | M24: =F24 -> 6 | N24: {=ROUNDUP(IF(EQ(A24, ""),L24*INDEX(UncertaintyFactors!$C$2:$D$7, M24, 1), 0), 1)} -> 0 | O24: {=ROUNDUP(IF(EQ(A24, ""), L24*INDEX(UncertaintyFactors!$C$2:$D$7, M24, 2), 0), 1)} -> 0
D25: 0 | F25: 6 | G25: {=ROUNDUP(IF(EQ(A25, ""),E25*INDEX(UncertaintyFactors!$C$2:$D$7, F25, 1), 0), 1)} -> 0 | H25: {=ROUNDUP(IF(EQ(A25, ""), E25*INDEX(UncertaintyFactors!$C$2:$D$7, F25, 2), 0), 1)} -> 0 | L25: =E25-(E25*D25) -> 0 | M25: =F25 -> 6 | N25: {=ROUNDUP(IF(EQ(A25, ""),L25*INDEX(UncertaintyFactors!$C$2:$D$7, M25, 1), 0), 1)} -> 0 | O25: {=ROUNDUP(IF(EQ(A25, ""), L25*INDEX(UncertaintyFactors!$C$2:$D$7, M25, 2), 0), 1)} -> 0
D26: 0 | F26: 6 | G26: {=ROUNDUP(IF(EQ(A26, ""),E26*INDEX(UncertaintyFactors!$C$2:$D$7, F26, 1), 0), 1)} -> 0 | H26: {=ROUNDUP(IF(EQ(A26, ""), E26*INDEX(UncertaintyFactors!$C$2:$D$7, F26, 2), 0), 1)} -> 0 | L26: =E26-(E26*D26) -> 0 | M26: =F26 -> 6 | N26: {=ROUNDUP(IF(EQ(A26, ""),L26*INDEX(UncertaintyFactors!$C$2:$D$7, M26, 1), 0), 1)} -> 0 | O26: {=ROUNDUP(IF(EQ(A26, ""), L26*INDEX(UncertaintyFactors!$C$2:$D$7, M26, 2), 0), 1)} -> 0
D27: 0 | F27: 6 | G27: {=ROUNDUP(IF(EQ(A27, ""),E27*INDEX(UncertaintyFactors!$C$2:$D$7, F27, 1), 0), 1)} -> 0 | H27: {=ROUNDUP(IF(EQ(A27, ""), E27*INDEX(UncertaintyFactors!$C$2:$D$7, F27, 2), 0), 1)} -> 0 | L27: =E27-(E27*D27) -> 0 | M27: =F27 -> 6 | N27: {=ROUNDUP(IF(EQ(A27, ""),L27*INDEX(UncertaintyFactors!$C$2:$D$7, M27, 1), 0), 1)} -> 0 | O27: {=ROUNDUP(IF(EQ(A27, ""), L27*INDEX(UncertaintyFactors!$C$2:$D$7, M27, 2), 0), 1)} -> 0
D28: 0 | F28: 6 | G28: {=ROUNDUP(IF(EQ(A28, ""),E28*INDEX(UncertaintyFactors!$C$2:$D$7, F28, 1), 0), 1)} -> 0 | H28: {=ROUNDUP(IF(EQ(A28, ""), E28*INDEX(UncertaintyFactors!$C$2:$D$7, F28, 2), 0), 1)} -> 0 | L28: =E28-(E28*D28) -> 0 | M28: =F28 -> 6 | N28: {=ROUNDUP(IF(EQ(A28, ""),L28*INDEX(UncertaintyFactors!$C$2:$D$7, M28, 1), 0), 1)} -> 0 | O28: {=ROUNDUP(IF(EQ(A28, ""), L28*INDEX(UncertaintyFactors!$C$2:$D$7, M28, 2), 0), 1)} -> 0
D29: 0 | F29: 6 | G29: {=ROUNDUP(IF(EQ(A29, ""),E29*INDEX(UncertaintyFactors!$C$2:$D$7, F29, 1), 0), 1)} -> 0 | H29: {=ROUNDUP(IF(EQ(A29, ""), E29*INDEX(UncertaintyFactors!$C$2:$D$7, F29, 2), 0), 1)} -> 0 | L29: =E29-(E29*D29) -> 0 | M29: =F29 -> 6 | N29: {=ROUNDUP(IF(EQ(A29, ""),L29*INDEX(UncertaintyFactors!$C$2:$D$7, M29, 1), 0), 1)} -> 0 | O29: {=ROUNDUP(IF(EQ(A29, ""), L29*INDEX(UncertaintyFactors!$C$2:$D$7, M29, 2), 0), 1)} -> 0
... D31: 0 | F31: 5 | G31: {=ROUNDUP(IF(EQ(A31, ""),E31*INDEX(UncertaintyFactors!$C$2:$D$7, F31, 1), 0), 1)} -> 0 | H31: {=ROUNDUP(IF(EQ(A31, ""), E31*INDEX(UncertaintyFactors!$C$2:$D$7, F31, 2), 0), 1)} -> 0 | L31: =E31-(E31*D31) -> 0 | M31: =F31 -> 5 | N31: {=ROUNDUP(IF(EQ(A31, ""),L31*INDEX(UncertaintyFactors!$C$2:$D$7, M31, 1), 0), 1)} -> 0 | O31: {=ROUNDUP(IF(EQ(A31, ""), L31*INDEX(UncertaintyFactors!$C$2:$D$7, M31, 2), 0), 1)} -> 0
E32: =ROUNDUP(SUM(E7:E30),0) -> 0 | F32: =AVERAGE(F7:F31) -> 5.96 | G32: =ROUNDUP(SUM(G7:G30),0) -> 0 | H32: =ROUNDUP(SUM(H7:H30),0) -> 0 | L32: =ROUNDUP(SUM(L7:L30),0) -> 0 | M32: =F32 -> 5.96 | N32: =ROUNDUP(SUM(N7:N30),0) -> 0 | O32: =ROUNDUP(SUM(O7:O30),0) -> 0
E33: Avg Hours | G33: =ROUNDUP(AVERAGE(G32:H32),0) -> 0 | L33: Avg Hours | N33: =ROUNDUP(AVERAGE(N32:O32),0) -> 0

Sheet Design
B1: TO BE FILLED IN BY THE PERSON WORKING ON THE ESTIMATE
B2: Name | H2: 0 | I2: Contigency / Confidence level
B3: Date | C3: 45020 | H3: =ROUNDUP(G33*H2,0) -> 0 | I3: Contingency Hours
B4: Total Hours | C4: =ROUNDUP(sum(G33,H3),0) -> 0 | M4: Total AI Efficacy Hours | N4: =ROUNDUP(SUM(O33,H3),0) -> 0
B5: VERIFIED BY
B6: Task | C6: Description | D6: AI Efficacy | E6: HOURS | F6: Conf | G6: Low Hrs | H6: High Hrs | I6: Assumptions | J6: Exclusions | K6: Reference links | L6: AI Efficacy Asssumptions (Internal use only) | M6: AI Efficacy HOURS | N6: Conf | O6: Low Hrs | P6: High Hrs
B7: User flow & IA | D7: 0.07 | F7: 6 | G7: {=ROUNDUP(IF(EQ(A7, ""),E7*INDEX(UncertaintyFactors!$C$2:$D$7, F7, 1), 0), 1)} -> 0 | H7: {=ROUNDUP(IF(EQ(A7, ""), E7*INDEX(UncertaintyFactors!$C$2:$D$7, F7, 2), 0), 1)} -> 0 | M7: =E7-(E7*D7) -> 0 | N7: =F7 -> 6 | O7: {=ROUNDUP(IF(EQ(A7, ""),M7*INDEX(UncertaintyFactors!$C$2:$D$7, N7, 1), 0), 1)} -> 0 | P7: {=ROUNDUP(IF(EQ(A7, ""), M7*INDEX(UncertaintyFactors!$C$2:$D$7, N7, 2), 0), 1)} -> 0
B8: Conceptualization + Wireframing | D8: 0 | F8: 6 | G8: {=ROUNDUP(IF(EQ(A8, ""),E8*INDEX(UncertaintyFactors!$C$2:$D$7, F8, 1), 0), 1)} -> 0 | H8: {=ROUNDUP(IF(EQ(A8, ""), E8*INDEX(UncertaintyFactors!$C$2:$D$7, F8, 2), 0), 1)} -> 0 | M8: =E8-(E8*D8) -> 0 | N8: =F8 -> 6 | O8: {=ROUNDUP(IF(EQ(A8, ""),M8*INDEX(UncertaintyFactors!$C$2:$D$7, N8, 1), 0), 1)} -> 0 | P8: {=ROUNDUP(IF(EQ(A8, ""), M8*INDEX(UncertaintyFactors!$C$2:$D$7, N8, 2), 0), 1)} -> 0
B9: Hi-Fi Designs | D9: 0 | F9: 6 | G9: {=ROUNDUP(IF(EQ(A9, ""),E9*INDEX(UncertaintyFactors!$C$2:$D$7, F9, 1), 0), 1)} -> 0 | H9: {=ROUNDUP(IF(EQ(A9, ""), E9*INDEX(UncertaintyFactors!$C$2:$D$7, F9, 2), 0), 1)} -> 0 | M9: =E9-(E9*D9) -> 0 | N9: =F9 -> 6 | O9: {=ROUNDUP(IF(EQ(A9, ""),M9*INDEX(UncertaintyFactors!$C$2:$D$7, N9, 1), 0), 1)} -> 0 | P9: {=ROUNDUP(IF(EQ(A9, ""), M9*INDEX(UncertaintyFactors!$C$2:$D$7, N9, 2), 0), 1)} -> 0
B10: Prototype | D10: 0.05 | F10: 6 | G10: {=ROUNDUP(IF(EQ(A10, ""),E10*INDEX(UncertaintyFactors!$C$2:$D$7, F10, 1), 0), 1)} -> 0 | H10: {=ROUNDUP(IF(EQ(A10, ""), E10*INDEX(UncertaintyFactors!$C$2:$D$7, F10, 2), 0), 1)} -> 0 | M10: =E10-(E10*D10) -> 0 | N10: =F10 -> 6 | O10: {=ROUNDUP(IF(EQ(A10, ""),M10*INDEX(UncertaintyFactors!$C$2:$D$7, N10, 1), 0), 1)} -> 0 | P10: {=ROUNDUP(IF(EQ(A10, ""), M10*INDEX(UncertaintyFactors!$C$2:$D$7, N10, 2), 0), 1)} -> 0
B11: Documentation | D11: 0.2 | F11: 6 | G11: {=ROUNDUP(IF(EQ(A11, ""),E11*INDEX(UncertaintyFactors!$C$2:$D$7, F11, 1), 0), 1)} -> 0 | H11: {=ROUNDUP(IF(EQ(A11, ""), E11*INDEX(UncertaintyFactors!$C$2:$D$7, F11, 2), 0), 1)} -> 0 | M11: =E11-(E11*D11) -> 0 | N11: =F11 -> 6 | O11: {=ROUNDUP(IF(EQ(A11, ""),M11*INDEX(UncertaintyFactors!$C$2:$D$7, N11, 1), 0), 1)} -> 0 | P11: {=ROUNDUP(IF(EQ(A11, ""), M11*INDEX(UncertaintyFactors!$C$2:$D$7, N11, 2), 0), 1)} -> 0
B12: Project Communication | D12: 0.05 | F12: 6 | G12: {=ROUNDUP(IF(EQ(A12, ""),E12*INDEX(UncertaintyFactors!$C$2:$D$7, F12, 1), 0), 1)} -> 0 | H12: {=ROUNDUP(IF(EQ(A12, ""), E12*INDEX(UncertaintyFactors!$C$2:$D$7, F12, 2), 0), 1)} -> 0 | M12: =E12-(E12*D12) -> 0 | N12: =F12 -> 6 | O12: {=ROUNDUP(IF(EQ(A12, ""),M12*INDEX(UncertaintyFactors!$C$2:$D$7, N12, 1), 0), 1)} -> 0 | P12: {=ROUNDUP(IF(EQ(A12, ""), M12*INDEX(UncertaintyFactors!$C$2:$D$7, N12, 2), 0), 1)} -> 0
D13: 0 | F13: 6 | G13: {=ROUNDUP(IF(EQ(A13, ""),E13*INDEX(UncertaintyFactors!$C$2:$D$7, F13, 1), 0), 1)} -> 0 | H13: {=ROUNDUP(IF(EQ(A13, ""), E13*INDEX(UncertaintyFactors!$C$2:$D$7, F13, 2), 0), 1)} -> 0 | M13: =E13-(E13*D13) -> 0 | N13: =F13 -> 6 | O13: {=ROUNDUP(IF(EQ(A13, ""),M13*INDEX(UncertaintyFactors!$C$2:$D$7, N13, 1), 0), 1)} -> 0 | P13: {=ROUNDUP(IF(EQ(A13, ""), M13*INDEX(UncertaintyFactors!$C$2:$D$7, N13, 2), 0), 1)} -> 0
D14: 0 | F14: 6 | G14: {=ROUNDUP(IF(EQ(A14, ""),E14*INDEX(UncertaintyFactors!$C$2:$D$7, F14, 1), 0), 1)} -> 0 | H14: {=ROUNDUP(IF(EQ(A14, ""), E14*INDEX(UncertaintyFactors!$C$2:$D$7, F14, 2), 0), 1)} -> 0 | M14: =E14-(E14*D14) -> 0 | N14: =F14 -> 6 | O14: {=ROUNDUP(IF(EQ(A14, ""),M14*INDEX(UncertaintyFactors!$C$2:$D$7, N14, 1), 0), 1)} -> 0 | P14: {=ROUNDUP(IF(EQ(A14, ""), M14*INDEX(UncertaintyFactors!$C$2:$D$7, N14, 2), 0), 1)} -> 0
D15: 0 | F15: 6 | G15: {=ROUNDUP(IF(EQ(A15, ""),E15*INDEX(UncertaintyFactors!$C$2:$D$7, F15, 1), 0), 1)} -> 0 | H15: {=ROUNDUP(IF(EQ(A15, ""), E15*INDEX(UncertaintyFactors!$C$2:$D$7, F15, 2), 0), 1)} -> 0 | M15: =E15-(E15*D15) -> 0 | N15: =F15 -> 6 | O15: {=ROUNDUP(IF(EQ(A15, ""),M15*INDEX(UncertaintyFactors!$C$2:$D$7, N15, 1), 0), 1)} -> 0 | P15: {=ROUNDUP(IF(EQ(A15, ""), M15*INDEX(UncertaintyFactors!$C$2:$D$7, N15, 2), 0), 1)} -> 0
D16: 0 | F16: 6 | G16: {=ROUNDUP(IF(EQ(A16, ""),E16*INDEX(UncertaintyFactors!$C$2:$D$7, F16, 1), 0), 1)} -> 0 | H16: {=ROUNDUP(IF(EQ(A16, ""), E16*INDEX(UncertaintyFactors!$C$2:$D$7, F16, 2), 0), 1)} -> 0 | M16: =E16-(E16*D16) -> 0 | N16: =F16 -> 6 | O16: {=ROUNDUP(IF(EQ(A16, ""),M16*INDEX(UncertaintyFactors!$C$2:$D$7, N16, 1), 0), 1)} -> 0 | P16: {=ROUNDUP(IF(EQ(A16, ""), M16*INDEX(UncertaintyFactors!$C$2:$D$7, N16, 2), 0), 1)} -> 0
D17: 0.05 | F17: 6 | G17: {=ROUNDUP(IF(EQ(A17, ""),E17*INDEX(UncertaintyFactors!$C$2:$D$7, F17, 1), 0), 1)} -> 0 | H17: {=ROUNDUP(IF(EQ(A17, ""), E17*INDEX(UncertaintyFactors!$C$2:$D$7, F17, 2), 0), 1)} -> 0 | M17: =E17-(E17*D17) -> 0 | N17: =F17 -> 6 | O17: {=ROUNDUP(IF(EQ(A17, ""),M17*INDEX(UncertaintyFactors!$C$2:$D$7, N17, 1), 0), 1)} -> 0 | P17: {=ROUNDUP(IF(EQ(A17, ""), M17*INDEX(UncertaintyFactors!$C$2:$D$7, N17, 2), 0), 1)} -> 0
D18: 0 | F18: 6 | G18: {=ROUNDUP(IF(EQ(A18, ""),E18*INDEX(UncertaintyFactors!$C$2:$D$7, F18, 1), 0), 1)} -> 0 | H18: {=ROUNDUP(IF(EQ(A18, ""), E18*INDEX(UncertaintyFactors!$C$2:$D$7, F18, 2), 0), 1)} -> 0 | M18: =E18-(E18*D18) -> 0 | N18: =F18 -> 6 | O18: {=ROUNDUP(IF(EQ(A18, ""),M18*INDEX(UncertaintyFactors!$C$2:$D$7, N18, 1), 0), 1)} -> 0 | P18: {=ROUNDUP(IF(EQ(A18, ""), M18*INDEX(UncertaintyFactors!$C$2:$D$7, N18, 2), 0), 1)} -> 0
D19: 0 | F19: 6 | G19: {=ROUNDUP(IF(EQ(A19, ""),E19*INDEX(UncertaintyFactors!$C$2:$D$7, F19, 1), 0), 1)} -> 0 | H19: {=ROUNDUP(IF(EQ(A19, ""), E19*INDEX(UncertaintyFactors!$C$2:$D$7, F19, 2), 0), 1)} -> 0 | M19: =E19-(E19*D19) -> 0 | N19: =F19 -> 6 | O19: {=ROUNDUP(IF(EQ(A19, ""),M19*INDEX(UncertaintyFactors!$C$2:$D$7, N19, 1), 0), 1)} -> 0 | P19: {=ROUNDUP(IF(EQ(A19, ""), M19*INDEX(UncertaintyFactors!$C$2:$D$7, N19, 2), 0), 1)} -> 0
D20: 0 | F20: 6 | G20: {=ROUNDUP(IF(EQ(A20, ""),E20*INDEX(UncertaintyFactors!$C$2:$D$7, F20, 1), 0), 1)} -> 0 | H20: {=ROUNDUP(IF(EQ(A20, ""), E20*INDEX(UncertaintyFactors!$C$2:$D$7, F20, 2), 0), 1)} -> 0 | M20: =E20-(E20*D20) -> 0 | N20: =F20 -> 6 | O20: {=ROUNDUP(IF(EQ(A20, ""),M20*INDEX(UncertaintyFactors!$C$2:$D$7, N20, 1), 0), 1)} -> 0 | P20: {=ROUNDUP(IF(EQ(A20, ""), M20*INDEX(UncertaintyFactors!$C$2:$D$7, N20, 2), 0), 1)} -> 0
D21: 0 | F21: 6 | G21: {=ROUNDUP(IF(EQ(A21, ""),E21*INDEX(UncertaintyFactors!$C$2:$D$7, F21, 1), 0), 1)} -> 0 | H21: {=ROUNDUP(IF(EQ(A21, ""), E21*INDEX(UncertaintyFactors!$C$2:$D$7, F21, 2), 0), 1)} -> 0 | M21: =E21-(E21*D21) -> 0 | N21: =F21 -> 6 | O21: {=ROUNDUP(IF(EQ(A21, ""),M21*INDEX(UncertaintyFactors!$C$2:$D$7, N21, 1), 0), 1)} -> 0 | P21: {=ROUNDUP(IF(EQ(A21, ""), M21*INDEX(UncertaintyFactors!$C$2:$D$7, N21, 2), 0), 1)} -> 0
D22: 0 | F22: 6 | G22: {=ROUNDUP(IF(EQ(A22, ""),E22*INDEX(UncertaintyFactors!$C$2:$D$7, F22, 1), 0), 1)} -> 0 | H22: {=ROUNDUP(IF(EQ(A22, ""), E22*INDEX(UncertaintyFactors!$C$2:$D$7, F22, 2), 0), 1)} -> 0 | M22: =E22-(E22*D22) -> 0 | N22: =F22 -> 6 | O22: {=ROUNDUP(IF(EQ(A22, ""),M22*INDEX(UncertaintyFactors!$C$2:$D$7, N22, 1), 0), 1)} -> 0 | P22: {=ROUNDUP(IF(EQ(A22, ""), M22*INDEX(UncertaintyFactors!$C$2:$D$7, N22, 2), 0), 1)} -> 0
D23: 0 | F23: 6 | G23: {=ROUNDUP(IF(EQ(A23, ""),E23*INDEX(UncertaintyFactors!$C$2:$D$7, F23, 1), 0), 1)} -> 0 | H23: {=ROUNDUP(IF(EQ(A23, ""), E23*INDEX(UncertaintyFactors!$C$2:$D$7, F23, 2), 0), 1)} -> 0 | M23: =E23-(E23*D23) -> 0 | N23: =F23 -> 6 | O23: {=ROUNDUP(IF(EQ(A23, ""),M23*INDEX(UncertaintyFactors!$C$2:$D$7, N23, 1), 0), 1)} -> 0 | P23: {=ROUNDUP(IF(EQ(A23, ""), M23*INDEX(UncertaintyFactors!$C$2:$D$7, N23, 2), 0), 1)} -> 0
D24: 0 | F24: 6 | G24: {=ROUNDUP(IF(EQ(A24, ""),E24*INDEX(UncertaintyFactors!$C$2:$D$7, F24, 1), 0), 1)} -> 0 | H24: {=ROUNDUP(IF(EQ(A24, ""), E24*INDEX(UncertaintyFactors!$C$2:$D$7, F24, 2), 0), 1)} -> 0 | M24: =E24-(E24*D24) -> 0 | N24: =F24 -> 6 | O24: {=ROUNDUP(IF(EQ(A24, ""),M24*INDEX(UncertaintyFactors!$C$2:$D$7, N24, 1), 0), 1)} -> 0 | P24: {=ROUNDUP(IF(EQ(A24, ""), M24*INDEX(UncertaintyFactors!$C$2:$D$7, N24, 2), 0), 1)} -> 0
... D30: 0 | F30: 6 | G30: {=ROUNDUP(IF(EQ(A30, ""),E30*INDEX(UncertaintyFactors!$C$2:$D$7, F30, 1), 0), 1)} -> 0 | H30: {=ROUNDUP(IF(EQ(A30, ""), E30*INDEX(UncertaintyFactors!$C$2:$D$7, F30, 2), 0), 1)} -> 0 | M30: =E30-(E30*D30) -> 0 | N30: =F30 -> 6 | O30: {=ROUNDUP(IF(EQ(A30, ""),M30*INDEX(UncertaintyFactors!$C$2:$D$7, N30, 1), 0), 1)} -> 0 | P30: {=ROUNDUP(IF(EQ(A30, ""), M30*INDEX(UncertaintyFactors!$C$2:$D$7, N30, 2), 0), 1)} -> 0
D31: 0 | E31: 0 | F31: 6 | G31: {=ROUNDUP(IF(EQ(A31, ""),E31*INDEX(UncertaintyFactors!$C$2:$D$7, F31, 1), 0), 1)} -> 0 | H31: {=ROUNDUP(IF(EQ(A31, ""), E31*INDEX(UncertaintyFactors!$C$2:$D$7, F31, 2), 0), 1)} -> 0 | M31: =E31-(E31*D31) -> 0 | N31: =F31 -> 6 | O31: {=ROUNDUP(IF(EQ(A31, ""),M31*INDEX(UncertaintyFactors!$C$2:$D$7, N31, 1), 0), 1)} -> 0 | P31: {=ROUNDUP(IF(EQ(A31, ""), M31*INDEX(UncertaintyFactors!$C$2:$D$7, N31, 2), 0), 1)} -> 0
E32: =ROUNDUP(SUM(E7:E31),0) -> 0 | F32: =AVERAGE(F7:F31) -> 6 | G32: =ROUNDUP(SUM(G7:G31),0) -> 0 | H32: =ROUNDUP(SUM(H7:H31),0) -> 0 | M32: 40 | N32: =F32 -> 6 | O32: =ROUNDUP(SUM(O7:O30),0) -> 0 | P32: =ROUNDUP(SUM(P7:P30),0) -> 0
E33: Avg Hours | G33: =ROUNDUP(AVERAGE(G32:H32),0) -> 0 | M33: Avg Hours | O33: =ROUNDUP(AVERAGE(O32:P32),0) -> 0

Sheet Backend
B1: TO BE FILLED IN BY THE PERSON WORKING ON THE ESTIMATE
B2: Name | E2: Sr. DEV | F2: DEV | H2: 0 | I2: Contigency / Confidence level | L2: Sr. DEV | M2: DEV
B3: Date | C3: 45525 | E3: =ROUNDUP(C4/2,0) -> 0 | F3: =ROUNDUP(C4/2,0) -> 0 | H3: =ROUNDUP(G87*H2,0) -> 0 | I3: Contingency Hours | L3: =ROUNDUP(M4/2,0) -> 0 | M3: =ROUNDUP(M4/2,0) -> 0
B4: Total Hours | C4: =ROUNDUP(SUM(G87,H3),0) -> 0 | L4: Total AI Efficacy Hours | M4: =ROUNDUP(SUM(N87,H3),0) -> 0 | N4: =(C4-M4)/C4 -> #DIV/0!
B5: VERIFIED BY
B6: Task | C6: Description | D6: AI Efficacy | E6: HOURS | F6: Conf | G6: Low Hrs | H6: High Hrs | I6: Assumptions | J6: Proposed Solution | K6: Reference links | L6: AI Efficacy HOURS | M6: Conf | N6: Low Hrs | O6: High Hrs
D7: 0 | F7: 6 | G7: {=ROUNDUP(IF(EQ(A7, ""),E7*INDEX(UncertaintyFactors!$C$2:$D$7, F7, 1), 0), 1)} -> 0 | H7: {=ROUNDUP(IF(EQ(A7, ""), E7*INDEX(UncertaintyFactors!$C$2:$D$7, F7, 2), 0), 1)} -> 0 | L7: =E7-(E7*D7) -> 0 | M7: =F7 -> 6 | N7: {=ROUNDUP(IF(EQ(A7, ""),L7*INDEX(UncertaintyFactors!$C$2:$D$7, M7, 1), 0), 1)} -> 0 | O7: {=ROUNDUP(IF(EQ(A7, ""), L7*INDEX(UncertaintyFactors!$C$2:$D$7, M7, 2), 0), 1)} -> 0
D8: 0 | F8: 6 | G8: {=ROUNDUP(IF(EQ(A8, ""),E8*INDEX(UncertaintyFactors!$C$2:$D$7, F8, 1), 0), 1)} -> 0 | H8: {=ROUNDUP(IF(EQ(A8, ""), E8*INDEX(UncertaintyFactors!$C$2:$D$7, F8, 2), 0), 1)} -> 0 | L8: =E8-(E8*D8) -> 0 | M8: =F8 -> 6 | N8: {=ROUNDUP(IF(EQ(A8, ""),L8*INDEX(UncertaintyFactors!$C$2:$D$7, M8, 1), 0), 1)} -> 0 | O8: {=ROUNDUP(IF(EQ(A8, ""), L8*INDEX(UncertaintyFactors!$C$2:$D$7, M8, 2), 0), 1)} -> 0
D9: 0 | F9: 6 | G9: {=ROUNDUP(IF(EQ(A9, ""),E9*INDEX(UncertaintyFactors!$C$2:$D$7, F9, 1), 0), 1)} -> 0 | H9: {=ROUNDUP(IF(EQ(A9, ""), E9*INDEX(UncertaintyFactors!$C$2:$D$7, F9, 2), 0), 1)} -> 0 | L9: =E9-(E9*D9) -> 0 | M9: =F9 -> 6 | N9: {=ROUNDUP(IF(EQ(A9, ""),L9*INDEX(UncertaintyFactors!$C$2:$D$7, M9, 1), 0), 1)} -> 0 | O9: {=ROUNDUP(IF(EQ(A9, ""), L9*INDEX(UncertaintyFactors!$C$2:$D$7, M9, 2), 0), 1)} -> 0
D10: 0 | F10: 6 | G10: {=ROUNDUP(IF(EQ(A10, ""),E10*INDEX(UncertaintyFactors!$C$2:$D$7, F10, 1), 0), 1)} -> 0 | H10: {=ROUNDUP(IF(EQ(A10, ""), E10*INDEX(UncertaintyFactors!$C$2:$D$7, F10, 2), 0), 1)} -> 0 | L10: =E10-(E10*D10) -> 0 | M10: =F10 -> 6 | N10: {=ROUNDUP(IF(EQ(A10, ""),L10*INDEX(UncertaintyFactors!$C$2:$D$7, M10, 1), 0), 1)} -> 0 | O10: {=ROUNDUP(IF(EQ(A10, ""), L10*INDEX(UncertaintyFactors!$C$2:$D$7, M10, 2), 0), 1)} -> 0
D11: 0 | F11: 6 | G11: {=ROUNDUP(IF(EQ(A11, ""),E11*INDEX(UncertaintyFactors!$C$2:$D$7, F11, 1), 0), 1)} -> 0 | H11: {=ROUNDUP(IF(EQ(A11, ""), E11*INDEX(UncertaintyFactors!$C$2:$D$7, F11, 2), 0), 1)} -> 0 | L11: =E11-(E11*D11) -> 0 | M11: =F11 -> 6 | N11: {=ROUNDUP(IF(EQ(A11, ""),L11*INDEX(UncertaintyFactors!$C$2:$D$7, M11, 1), 0), 1)} -> 0 | O11: {=ROUNDUP(IF(EQ(A11, ""), L11*INDEX(UncertaintyFactors!$C$2:$D$7, M11, 2), 0), 1)} -> 0
D12: 0 | F12: 6 | G12: {=ROUNDUP(IF(EQ(A12, ""),E12*INDEX(UncertaintyFactors!$C$2:$D$7, F12, 1), 0), 1)} -> 0 | H12: {=ROUNDUP(IF(EQ(A12, ""), E12*INDEX(UncertaintyFactors!$C$2:$D$7, F12, 2), 0), 1)} -> 0 | L12: =E12-(E12*D12) -> 0 | M12: =F12 -> 6 | N12: {=ROUNDUP(IF(EQ(A12, ""),L12*INDEX(UncertaintyFactors!$C$2:$D$7, M12, 1), 0), 1)} -> 0 | O12: {=ROUNDUP(IF(EQ(A12, ""), L12*INDEX(UncertaintyFactors!$C$2:$D$7, M12, 2), 0), 1)} -> 0
D13: 0 | F13: 6 | G13: {=ROUNDUP(IF(EQ(A13, ""),E13*INDEX(UncertaintyFactors!$C$2:$D$7, F13, 1), 0), 1)} -> 0 | H13: {=ROUNDUP(IF(EQ(A13, ""), E13*INDEX(UncertaintyFactors!$C$2:$D$7, F13, 2), 0), 1)} -> 0 | L13: =E13-(E13*D13) -> 0 | M13: =F13 -> 6 | N13: {=ROUNDUP(IF(EQ(A13, ""),L13*INDEX(UncertaintyFactors!$C$2:$D$7, M13, 1), 0), 1)} -> 0 | O13: {=ROUNDUP(IF(EQ(A13, ""), L13*INDEX(UncertaintyFactors!$C$2:$D$7, M13, 2), 0), 1)} -> 0
D14: 0 | F14: 6 | G14: {=ROUNDUP(IF(EQ(A14, ""),E14*INDEX(UncertaintyFactors!$C$2:$D$7, F14, 1), 0), 1)} -> 0 | H14: {=ROUNDUP(IF(EQ(A14, ""), E14*INDEX(UncertaintyFactors!$C$2:$D$7, F14, 2), 0), 1)} -> 0 | L14: =E14-(E14*D14) -> 0 | M14: =F14 -> 6 | N14: {=ROUNDUP(IF(EQ(A14, ""),L14*INDEX(UncertaintyFactors!$C$2:$D$7, M14, 1), 0), 1)} -> 0 | O14: {=ROUNDUP(IF(EQ(A14, ""), L14*INDEX(UncertaintyFactors!$C$2:$D$7, M14, 2), 0), 1)} -> 0
D15: 0 | F15: 6 | G15: {=ROUNDUP(IF(EQ(A15, ""),E15*INDEX(UncertaintyFactors!$C$2:$D$7, F15, 1), 0), 1)} -> 0 | H15: {=ROUNDUP(IF(EQ(A15, ""), E15*INDEX(UncertaintyFactors!$C$2:$D$7, F15, 2), 0), 1)} -> 0 | L15: =E15-(E15*D15) -> 0 | M15: =F15 -> 6 | N15: {=ROUNDUP(IF(EQ(A15, ""),L15*INDEX(UncertaintyFactors!$C$2:$D$7, M15, 1), 0), 1)} -> 0 | O15: {=ROUNDUP(IF(EQ(A15, ""), L15*INDEX(UncertaintyFactors!$C$2:$D$7, M15, 2), 0), 1)} -> 0
D16: 0 | F16: 6 | G16: {=ROUNDUP(IF(EQ(A16, ""),E16*INDEX(UncertaintyFactors!$C$2:$D$7, F16, 1), 0), 1)} -> 0 | H16: {=ROUNDUP(IF(EQ(A16, ""), E16*INDEX(UncertaintyFactors!$C$2:$D$7, F16, 2), 0), 1)} -> 0 | L16: =E16-(E16*D16) -> 0 | M16: =F16 -> 6 | N16: {=ROUNDUP(IF(EQ(A16, ""),L16*INDEX(UncertaintyFactors!$C$2:$D$7, M16, 1), 0), 1)} -> 0 | O16: {=ROUNDUP(IF(EQ(A16, ""), L16*INDEX(UncertaintyFactors!$C$2:$D$7, M16, 2), 0), 1)} -> 0
D17: 0 | F17: 6 | G17: {=ROUNDUP(IF(EQ(A17, ""),E17*INDEX(UncertaintyFactors!$C$2:$D$7, F17, 1), 0), 1)} -> 0 | H17: {=ROUNDUP(IF(EQ(A17, ""), E17*INDEX(UncertaintyFactors!$C$2:$D$7, F17, 2), 0), 1)} -> 0 | L17: =E17-(E17*D17) -> 0 | M17: =F17 -> 6 | N17: {=ROUNDUP(IF(EQ(A17, ""),L17*INDEX(UncertaintyFactors!$C$2:$D$7, M17, 1), 0), 1)} -> 0 | O17: {=ROUNDUP(IF(EQ(A17, ""), L17*INDEX(UncertaintyFactors!$C$2:$D$7, M17, 2), 0), 1)} -> 0
D18: 0 | F18: 6 | G18: {=ROUNDUP(IF(EQ(A18, ""),E18*INDEX(UncertaintyFactors!$C$2:$D$7, F18, 1), 0), 1)} -> 0 | H18: {=ROUNDUP(IF(EQ(A18, ""), E18*INDEX(UncertaintyFactors!$C$2:$D$7, F18, 2), 0), 1)} -> 0 | L18: =E18-(E18*D18) -> 0 | M18: =F18 -> 6 | N18: {=ROUNDUP(IF(EQ(A18, ""),L18*INDEX(UncertaintyFactors!$C$2:$D$7, M18, 1), 0), 1)} -> 0 | O18: {=ROUNDUP(IF(EQ(A18, ""), L18*INDEX(UncertaintyFactors!$C$2:$D$7, M18, 2), 0), 1)} -> 0
... D85: 0 | F85: 6 | G85: {=ROUNDUP(IF(EQ(A85, ""),E85*INDEX(UncertaintyFactors!$C$2:$D$7, F85, 1), 0), 1)} -> 0 | H85: {=ROUNDUP(IF(EQ(A85, ""), E85*INDEX(UncertaintyFactors!$C$2:$D$7, F85, 2), 0), 1)} -> 0 | L85: =E85-(E85*D85) -> 0 | M85: =F85 -> 6 | N85: {=ROUNDUP(IF(EQ(A85, ""),L85*INDEX(UncertaintyFactors!$C$2:$D$7, M85, 1), 0), 1)} -> 0 | O85: {=ROUNDUP(IF(EQ(A85, ""), L85*INDEX(UncertaintyFactors!$C$2:$D$7, M85, 2), 0), 1)} -> 0
E86: =ROUNDUP(SUM(E7:E85),0) -> 0 | F86: =AVERAGE(F7:F85) -> 6 | G86: =ROUNDUP(SUM(G7:G85),0) -> 0 | H86: =ROUNDUP(SUM(H7:H85),0) -> 0 | L86: =ROUNDUP(SUM(L7:L85),0) -> 0 | M86: =F86 -> 6 | N86: =ROUNDUP(SUM(N7:N85),0) -> 0 | O86: =ROUNDUP(SUM(O7:O85),0) -> 0
E87: Avg Hours | G87: =ROUNDUP(AVERAGE(G86:H86),0) -> 0 | L87: Avg Hours | N87: =ROUNDUP(AVERAGE(N86:O86),0) -> 0

Sheet Sample set - BE
B1: TO BE FILLED IN BY THE PERSON WORKING ON THE ESTIMATE
B2: Name | D2: Sr. DEV | E2: DEV | G2: 0.1 | H2: Contigency / Confidence level
B3: Date | C3: 45020 | D3: =ROUNDUP(C4/2,0) -> 788 | E3: =ROUNDUP(C4/2,0) -> 788 | G3: =ROUNDUP(F87*G2,0) -> 144 | H3: Contingency Hours
B4: Total Hours | C4: =ROUNDUP(SUM(F87,G3),0) -> 1576
B5: VERIFIED BY
B6: Task | C6: Description | D6: HOURS | E6: Conf | F6: Low Hrs | G6: High Hrs | H6: Assumptions | I6: Proposed Solution | J6: Reference links
B7: Base Project Setup & Onboarding | D7: 16 | E7: 5 | F7: {=ROUNDUP(IF(EQ(A7, ""),D7*INDEX(UncertaintyFactors!$C$2:$D$7, E7, 1), 0), 1)} -> 16 | G7: {=ROUNDUP(IF(EQ(A7, ""), D7*INDEX(UncertaintyFactors!$C$2:$D$7, E7, 2), 0), 1)} -> 20 | H7: Assuming the scope of this engagement will be limited to pages under the domain https://www.leduc.ca/ with merged data from cityworks.leduc.ca (only GIS Maps in embedded format) ,elections.leduc.ca , , live.leduc.ca & photo.leduc.ca only. This will still leave scope for being able to create microsites in future. Assuming the total count of calculators across the platform to be 5. These calculators are also not expected to store any data, but just provide users with a calculated output based on the input & business logic applicable. These calculators are also not expected to be doing any kind of database queries or API calls. Assuming the PDF to web conversion will be needed only for Form pages. The ability to create webforms & have them styled aligning with the Brand guidelines will be built in the Migrated portal. The ceation of a total of 10 different forms will be a part of scope of this engagement. Any other PDF to form conversions can be taken up by City of Leduc's authoring team with training & handoff. Assuming all webform submissions will be stored on Drupal only. Assuming there will be a single content moderation system required for all different content templates taking the content through stages: draft > Review > Publish > Archive. Drupal is flexible to allow creation of new states, transitions, access-control in a moderation system. This assumption is made to be able to scope out & estimate the work here only. Assuming a cap of 270 content entities to be migrated/created during the Migration & the same includes merger of content from microsites listed above being merged. Assuming full access to Drupal 7 instance responsible for current site will be provided as a source for Migration. Assuming no use of inline styles, broken HTML in Drupal 7 content across different pages. Assuming the multilingual implementation will need to be based on Google translate only. No native translation support is required as a part of this Migration. Assuming the site seach on the Migrated portal will be powered from the content within the portal itself & no external systems will be involved in search results. Assuming all content used/consumed by end-users will be created on the CMS itself i.e., no content-import from external systems is considered to be in-scope. Assuming for all items in the RFP marked as potential future integration, the Platform should be capable (if needed demonstrated as well). The features themselves aren't in scope for this engagement. Assuming no tweaks/branding to be considered in UI/X for the admin interface. Drupal's admin theme is responsive in nature & allows for the site maintenance via handheld devices as well. Assuming no activity other than content authoring to be conducted by logged in users on the site. End-users consuming information will be anonymous users only. Assuming we will be okay with a content freeze duration druring the go-live process (approx. 2 weeks). Assuming all content thats rendering on the current site via anm iframe will continue to render as iframes with the Migrated site for this engagement.
B8: Content Authoring | E8: 5 | F8: {=ROUNDUP(IF(EQ(A8, ""),D8*INDEX(UncertaintyFactors!$C$2:$D$7, E8, 1), 0), 1)} -> 0 | G8: {=ROUNDUP(IF(EQ(A8, ""), D8*INDEX(UncertaintyFactors!$C$2:$D$7, E8, 2), 0), 1)} -> 0
B9: Ability to create content of different types corresponding to different functions using different/similar layouts. | C9: Landing pages Events News Programs City Facilities Blogs PDF Directory Photo Gallery People (Council & Board Members) Departments Meeting Minutes | D9: 80 | E9: 4 | F9: {=ROUNDUP(IF(EQ(A9, ""),D9*INDEX(UncertaintyFactors!$C$2:$D$7, E9, 1), 0), 1)} -> 80 | G9: {=ROUNDUP(IF(EQ(A9, ""), D9*INDEX(UncertaintyFactors!$C$2:$D$7, E9, 2), 0), 1)} -> 120 | H9: Assuming only the below to be supported: Admin Audit Trail User Authentication Logs user authentication (login logout and request password). Admin Audit Trail Block Content Logs block content CUD events performed by the user. Admin Audit Trail Comment Logs comment CUD events performed by the user. Admin Audit Trail Entityqueue Logs entityqueue CUD events performed by the user. Admin Audit Trail File Logs file CUD events performed by the user. Admin Audit Trail Media Logs node CUD events performed by the user. Admin Audit Trail Menu Logs menu CUD events performed by the user. Admin Audit Trail Node Logs node CUD events performed by the user. Admin Audit Trail Redirect Logs redirect CUD events performed by the user. Admin Audit Trail Taxonomy Logs taxonomy vocabulary and term CUD events performed by the user. Admin Audit Trail User Logs user CUD events performed by the user. Admin Audit Trail Workflows Logs workflows events performed by the user.
B10: Ability to tag all different content-types with tags & categories. | D10: 4 | E10: 6 | F10: {=ROUNDUP(IF(EQ(A10, ""),D10*INDEX(UncertaintyFactors!$C$2:$D$7, E10, 1), 0), 1)} -> 4 | G10: {=ROUNDUP(IF(EQ(A10, ""), D10*INDEX(UncertaintyFactors!$C$2:$D$7, E10, 2), 0), 1)} -> 4
B11: Ability to create component & place them in specific regions as well assemble unique digital experiences using them | D11: 60 | E11: 5 | F11: {=ROUNDUP(IF(EQ(A11, ""),D11*INDEX(UncertaintyFactors!$C$2:$D$7, E11, 1), 0), 1)} -> 60 | G11: {=ROUNDUP(IF(EQ(A11, ""), D11*INDEX(UncertaintyFactors!$C$2:$D$7, E11, 2), 0), 1)} -> 75 | H11: Assuming a component Library of 20-30 visual components to build the Landing page content will be sufficient here. Assuming 10 different global re-usable blocks placeable in global regions i.e, header & footer/sidebar (Depending on the designs).
B12: Ability to create content using a basic content moderation process | D12: 40 | E12: 6 | F12: {=ROUNDUP(IF(EQ(A12, ""),D12*INDEX(UncertaintyFactors!$C$2:$D$7, E12, 1), 0), 1)} -> 40 | G12: {=ROUNDUP(IF(EQ(A12, ""), D12*INDEX(UncertaintyFactors!$C$2:$D$7, E12, 2), 0), 1)} -> 40 | H12: Assuming the basic content moderation process defined in the first row. Assuming content modetation dashboards for different states & notifications to follow accordingly on state transitions. Assuming the access control will be needed at a role & Content structure level only. This will not apply to url structure or single-user access for specific content.
B13: Ability to preview & restore old content revisions | D13: 16 | E13: 6 | F13: {=ROUNDUP(IF(EQ(A13, ""),D13*INDEX(UncertaintyFactors!$C$2:$D$7, E13, 1), 0), 1)} -> 16 | G13: {=ROUNDUP(IF(EQ(A13, ""), D13*INDEX(UncertaintyFactors!$C$2:$D$7, E13, 2), 0), 1)} -> 16
B14: Ability to schedule & publish content later at a time defined by content creator | D14: 16 | E14: 6 | F14: {=ROUNDUP(IF(EQ(A14, ""),D14*INDEX(UncertaintyFactors!$C$2:$D$7, E14, 1), 0), 1)} -> 16 | G14: {=ROUNDUP(IF(EQ(A14, ""), D14*INDEX(UncertaintyFactors!$C$2:$D$7, E14, 2), 0), 1)} -> 16
B15: Ability ot archive & export archived content list | D15: 16 | E15: 6 | F15: {=ROUNDUP(IF(EQ(A15, ""),D15*INDEX(UncertaintyFactors!$C$2:$D$7, E15, 1), 0), 1)} -> 16 | G15: {=ROUNDUP(IF(EQ(A15, ""), D15*INDEX(UncertaintyFactors!$C$2:$D$7, E15, 2), 0), 1)} -> 16
B16: Ability to manage media assets centrally | D16: 8 | E16: 6 | F16: {=ROUNDUP(IF(EQ(A16, ""),D16*INDEX(UncertaintyFactors!$C$2:$D$7, E16, 1), 0), 1)} -> 8 | G16: {=ROUNDUP(IF(EQ(A16, ""), D16*INDEX(UncertaintyFactors!$C$2:$D$7, E16, 2), 0), 1)} -> 8
B17: User Interactions | E17: 6 | F17: {=ROUNDUP(IF(EQ(A17, ""),D17*INDEX(UncertaintyFactors!$C$2:$D$7, E17, 1), 0), 1)} -> 0 | G17: {=ROUNDUP(IF(EQ(A17, ""), D17*INDEX(UncertaintyFactors!$C$2:$D$7, E17, 2), 0), 1)} -> 0
B18: Ability to subscribe to the newsletter | D18: 32 | E18: 5 | F18: {=ROUNDUP(IF(EQ(A18, ""),D18*INDEX(UncertaintyFactors!$C$2:$D$7, E18, 1), 0), 1)} -> 32 | G18: {=ROUNDUP(IF(EQ(A18, ""), D18*INDEX(UncertaintyFactors!$C$2:$D$7, E18, 2), 0), 1)} -> 40 | H18: Assuming the subscription data will reside on Drupal only & doesn't need to be integrated with a 3rd party newsletter system.
B19: Ability to see a site-wide ticker for general announcements | D19: 16 | E19: 6 | F19: {=ROUNDUP(IF(EQ(A19, ""),D19*INDEX(UncertaintyFactors!$C$2:$D$7, E19, 1), 0), 1)} -> 16 | G19: {=ROUNDUP(IF(EQ(A19, ""), D19*INDEX(UncertaintyFactors!$C$2:$D$7, E19, 2), 0), 1)} -> 16
B20: Ability to share pages on Social media | D20: 8 | E20: 6 | F20: {=ROUNDUP(IF(EQ(A20, ""),D20*INDEX(UncertaintyFactors!$C$2:$D$7, E20, 1), 0), 1)} -> 8 | G20: {=ROUNDUP(IF(EQ(A20, ""), D20*INDEX(UncertaintyFactors!$C$2:$D$7, E20, 2), 0), 1)} -> 8
B21: Ability to navigate through site sections using menu blocks with next level links | D21: 16 | E21: 6 | F21: {=ROUNDUP(IF(EQ(A21, ""),D21*INDEX(UncertaintyFactors!$C$2:$D$7, E21, 1), 0), 1)} -> 16 | G21: {=ROUNDUP(IF(EQ(A21, ""), D21*INDEX(UncertaintyFactors!$C$2:$D$7, E21, 2), 0), 1)} -> 16
B22: Ability to view dynamic content listing blocks for structured content | D22: 60 | E22: 6 | F22: {=ROUNDUP(IF(EQ(A22, ""),D22*INDEX(UncertaintyFactors!$C$2:$D$7, E22, 1), 0), 1)} -> 60 | G22: {=ROUNDUP(IF(EQ(A22, ""), D22*INDEX(UncertaintyFactors!$C$2:$D$7, E22, 2), 0), 1)} -> 60 | H22: Assuming 2 listing blocks/page for each of the below: - Events - News - Programs - City Facilities - Blogs - PDF Directory - Photo Gallery - People (Council & Board Members) - Departments - Meeting Minutes
B23: User Engagement & Tracking | E23: 6 | F23: {=ROUNDUP(IF(EQ(A23, ""),D23*INDEX(UncertaintyFactors!$C$2:$D$7, E23, 1), 0), 1)} -> 0 | G23: {=ROUNDUP(IF(EQ(A23, ""), D23*INDEX(UncertaintyFactors!$C$2:$D$7, E23, 2), 0), 1)} -> 0
B24: User login integration with Azure AD. | D24: 40 | E24: 6 | F24: {=ROUNDUP(IF(EQ(A24, ""),D24*INDEX(UncertaintyFactors!$C$2:$D$7, E24, 1), 0), 1)} -> 40 | G24: {=ROUNDUP(IF(EQ(A24, ""), D24*INDEX(UncertaintyFactors!$C$2:$D$7, E24, 2), 0), 1)} -> 40 | H24: Assuming Active Directory for authentication here & roles to be dictated by Active Directory. Assuming no SSO implementation to be in scope for this engagement.
B25: Ability to get support via a Live chatbot on some business critical pages. | D25: 8 | E25: 6 | F25: {=ROUNDUP(IF(EQ(A25, ""),D25*INDEX(UncertaintyFactors!$C$2:$D$7, E25, 1), 0), 1)} -> 8 | G25: {=ROUNDUP(IF(EQ(A25, ""), D25*INDEX(UncertaintyFactors!$C$2:$D$7, E25, 2), 0), 1)} -> 8 | H25: Assuming the chatbot will be a 3rd party integration here.
E26: 6 | F26: {=ROUNDUP(IF(EQ(A26, ""),D26*INDEX(UncertaintyFactors!$C$2:$D$7, E26, 1), 0), 1)} -> 0 | G26: {=ROUNDUP(IF(EQ(A26, ""), D26*INDEX(UncertaintyFactors!$C$2:$D$7, E26, 2), 0), 1)} -> 0
E27: 6 | F27: {=ROUNDUP(IF(EQ(A27, ""),D27*INDEX(UncertaintyFactors!$C$2:$D$7, E27, 1), 0), 1)} -> 0 | G27: {=ROUNDUP(IF(EQ(A27, ""), D27*INDEX(UncertaintyFactors!$C$2:$D$7, E27, 2), 0), 1)} -> 0
B28: Ability to create new forms & track + export submissions on Drupal. | D28: 60 | E28: 6 | F28: {=ROUNDUP(IF(EQ(A28, ""),D28*INDEX(UncertaintyFactors!$C$2:$D$7, E28, 1), 0), 1)} -> 60 | G28: {=ROUNDUP(IF(EQ(A28, ""), D28*INDEX(UncertaintyFactors!$C$2:$D$7, E28, 2), 0), 1)} -> 60 | H28: Assuming form widgets to not exceed the below list: - TextField - Text Area - Select List - Checkbox/es - Radio/s - File input Includes for creation of 10 different webforms & placing them across the sites.
B29: Event Calendar, SMS & Email notifications | D29: 80 | E29: 5 | F29: {=ROUNDUP(IF(EQ(A29, ""),D29*INDEX(UncertaintyFactors!$C$2:$D$7, E29, 1), 0), 1)} -> 80 | G29: {=ROUNDUP(IF(EQ(A29, ""), D29*INDEX(UncertaintyFactors!$C$2:$D$7, E29, 2), 0), 1)} -> 100 | H29: Assuming notifications for the following events: - Event creation - broadcast to all past attendees - Event registration - Confirmation email to the registered attendee. - Event start notification - N minutes before the start of the event with a link to join the event. - Thank you for a notification - At the closure/end of the webinar, thank the attendees along with a recording of the event (optional) Assuming the users registered for the event will not be able to login to the Platform. This will be a simple exportable entity & have no link with the registered users on the Platform.
E30: 6 | F30: {=ROUNDUP(IF(EQ(A30, ""),D30*INDEX(UncertaintyFactors!$C$2:$D$7, E30, 1), 0), 1)} -> 0 | G30: {=ROUNDUP(IF(EQ(A30, ""), D30*INDEX(UncertaintyFactors!$C$2:$D$7, E30, 2), 0), 1)} -> 0
B31: Content Discoverability | E31: 6 | F31: {=ROUNDUP(IF(EQ(A31, ""),D31*INDEX(UncertaintyFactors!$C$2:$D$7, E31, 1), 0), 1)} -> 0 | G31: {=ROUNDUP(IF(EQ(A31, ""), D31*INDEX(UncertaintyFactors!$C$2:$D$7, E31, 2), 0), 1)} -> 0
B32: Robust search covering for text documents & PDF with drill-down filters | D32: 100 | E32: 6 | F32: {=ROUNDUP(IF(EQ(A32, ""),D32*INDEX(UncertaintyFactors!$C$2:$D$7, E32, 1), 0), 1)} -> 100 | G32: {=ROUNDUP(IF(EQ(A32, ""), D32*INDEX(UncertaintyFactors!$C$2:$D$7, E32, 2), 0), 1)} -> 100 | H32: - Assuming the content in the PDF files also needs to be searchable. - Assuming a short delay for content to appear in search results is acceptable.
B33: Robust Information architecture presented via Navigation menu | D33: 20 | E33: 6 | F33: {=ROUNDUP(IF(EQ(A33, ""),D33*INDEX(UncertaintyFactors!$C$2:$D$7, E33, 1), 0), 1)} -> 20 | G33: {=ROUNDUP(IF(EQ(A33, ""), D33*INDEX(UncertaintyFactors!$C$2:$D$7, E33, 2), 0), 1)} -> 20 | H33: Assuming a simple 2-level navigation menu with featured content blocks in them. The footer to consist of flat menu links.
E34: 6 | F34: {=ROUNDUP(IF(EQ(A34, ""),D34*INDEX(UncertaintyFactors!$C$2:$D$7, E34, 1), 0), 1)} -> 0 | G34: {=ROUNDUP(IF(EQ(A34, ""), D34*INDEX(UncertaintyFactors!$C$2:$D$7, E34, 2), 0), 1)} -> 0
B35: SEO & Redirects Setup | D35: 60 | E35: 5 | F35: {=ROUNDUP(IF(EQ(A35, ""),D35*INDEX(UncertaintyFactors!$C$2:$D$7, E35, 1), 0), 1)} -> 60 | G35: {=ROUNDUP(IF(EQ(A35, ""), D35*INDEX(UncertaintyFactors!$C$2:$D$7, E35, 2), 0), 1)} -> 75 | H35: - Assuming the features needed from SEO perspective are as follows: -- GTM/GA integration -- Meta tags automated with manual overrides (Support for indexing control, OG tags, Page title, meta description, author, published/modified date etc.) - Assuming other analytics & marketing integration scripts e.g., hotjar will be added directly via GTM. Assuming all analytics to be driven only via GA dashboards & nothing to be tracked by the CMS/Platform chosen.
E36: 6 | F36: {=ROUNDUP(IF(EQ(A36, ""),D36*INDEX(UncertaintyFactors!$C$2:$D$7, E36, 1), 0), 1)} -> 0 | G36: {=ROUNDUP(IF(EQ(A36, ""), D36*INDEX(UncertaintyFactors!$C$2:$D$7, E36, 2), 0), 1)} -> 0
B37: Content Migration | E37: 6 | F37: {=ROUNDUP(IF(EQ(A37, ""),D37*INDEX(UncertaintyFactors!$C$2:$D$7, E37, 1), 0), 1)} -> 0 | G37: {=ROUNDUP(IF(EQ(A37, ""), D37*INDEX(UncertaintyFactors!$C$2:$D$7, E37, 2), 0), 1)} -> 0
B38: Automated Migration of structured content e.g., News, Events & Manual Migration for Landing Pages | D38: 320 | E38: 5 | F38: {=ROUNDUP(IF(EQ(A38, ""),D38*INDEX(UncertaintyFactors!$C$2:$D$7, E38, 1), 0), 1)} -> 320 | G38: {=ROUNDUP(IF(EQ(A38, ""), D38*INDEX(UncertaintyFactors!$C$2:$D$7, E38, 2), 0), 1)} -> 400 | H38: Assuming the total number of pages to be migrated over to be 500(including 270 pages mentioned in the RFP & approx. 230 pages for content review & edits).
B39: Ability to generate Micro-sites from content on the main site itself | D39: 120 | E39: 5 | F39: {=ROUNDUP(IF(EQ(A39, ""),D39*INDEX(UncertaintyFactors!$C$2:$D$7, E39, 1), 0), 1)} -> 120 | G39: {=ROUNDUP(IF(EQ(A39, ""), D39*INDEX(UncertaintyFactors!$C$2:$D$7, E39, 2), 0), 1)} -> 150 | H39: Assuming all Microsites (e.g., departments) will follow the same brand guidelines. Considering the same layout with different components can be represented giving the microsites a unique digital experience. Assuming the header & footer will also need to be overridden for these sites.
E40: 6 | F40: {=ROUNDUP(IF(EQ(A40, ""),D40*INDEX(UncertaintyFactors!$C$2:$D$7, E40, 1), 0), 1)} -> 0 | G40: {=ROUNDUP(IF(EQ(A40, ""), D40*INDEX(UncertaintyFactors!$C$2:$D$7, E40, 2), 0), 1)} -> 0
...

Sheet Frontend
A1: TO BE FILLED IN BY THE PERSON WORKING ON THE ESTIMATE
B2: Name | E2: Sr. FE | F2: FE | H2: 0 | I2: Contigency / Confidence level | L2: Sr. FE | M2: FE
B3: Date | E3: =ROUNDUP(C4/2,0) -> 0 | F3: =ROUNDUP(C4/2,0) -> 0 | H3: =ROUNDUP(G57*H2,0) -> 0 | I3: Contingency Hours | L3: =ROUNDUP(M4/2,0) -> 0 | M3: =ROUNDUP(M4/2,0) -> 0
B4: Total Hours | C4: =ROUND(SUM(G57,H3),0) -> 0 | L4: Total AI Efficacy Hours | M4: =ROUNDUP(SUM(L56,H3),0) -> 0
B5: VERIFIED BY
B6: Task | C6: Description | D6: AI Efficacy | E6: HOURS | F6: Conf | G6: Low Hrs | H6: High Hrs | I6: Assumptions | J6: Exclusions | K6: Reference links | L6: AI Efficacy HOURS | M6: Conf | N6: Low Hrs | O6: High Hrs
B7: Theme Setup | D7: 0 | F7: 6 | G7: {=ROUNDUP(IF(EQ(A7, ""),E7*INDEX(UncertaintyFactors!$C$2:$D$7, F7, 1), 0), 1)} -> 0 | H7: {=ROUNDUP(IF(EQ(A7, ""), E7*INDEX(UncertaintyFactors!$C$2:$D$7, F7, 2), 0), 1)} -> 0 | L7: =E7-(E7*D7) -> 0 | M7: =F7 -> 6 | N7: {=ROUNDUP(IF(EQ(A7, ""),L7*INDEX(UncertaintyFactors!$C$2:$D$7, M7, 1), 0), 1)} -> 0 | O7: {=ROUNDUP(IF(EQ(A7, ""), L7*INDEX(UncertaintyFactors!$C$2:$D$7, M7, 2), 0), 1)} -> 0
B8: Header | D8: 0 | F8: 6 | G8: {=ROUNDUP(IF(EQ(A8, ""),E8*INDEX(UncertaintyFactors!$C$2:$D$7, F8, 1), 0), 1)} -> 0 | H8: {=ROUNDUP(IF(EQ(A8, ""), E8*INDEX(UncertaintyFactors!$C$2:$D$7, F8, 2), 0), 1)} -> 0 | L8: =E8-(E8*D8) -> 0 | M8: =F8 -> 6 | N8: {=ROUNDUP(IF(EQ(A8, ""),L8*INDEX(UncertaintyFactors!$C$2:$D$7, M8, 1), 0), 1)} -> 0 | O8: {=ROUNDUP(IF(EQ(A8, ""), L8*INDEX(UncertaintyFactors!$C$2:$D$7, M8, 2), 0), 1)} -> 0
B9: Footer | D9: 0 | F9: 6 | G9: {=ROUNDUP(IF(EQ(A9, ""),E9*INDEX(UncertaintyFactors!$C$2:$D$7, F9, 1), 0), 1)} -> 0 | H9: {=ROUNDUP(IF(EQ(A9, ""), E9*INDEX(UncertaintyFactors!$C$2:$D$7, F9, 2), 0), 1)} -> 0 | L9: =E9-(E9*D9) -> 0 | M9: =F9 -> 6 | N9: {=ROUNDUP(IF(EQ(A9, ""),L9*INDEX(UncertaintyFactors!$C$2:$D$7, M9, 1), 0), 1)} -> 0 | O9: {=ROUNDUP(IF(EQ(A9, ""), L9*INDEX(UncertaintyFactors!$C$2:$D$7, M9, 2), 0), 1)} -> 0
B10: Navigation | D10: 0 | F10: 6 | G10: {=ROUNDUP(IF(EQ(A10, ""),E10*INDEX(UncertaintyFactors!$C$2:$D$7, F10, 1), 0), 1)} -> 0 | H10: {=ROUNDUP(IF(EQ(A10, ""), E10*INDEX(UncertaintyFactors!$C$2:$D$7, F10, 2), 0), 1)} -> 0 | L10: =E10-(E10*D10) -> 0 | M10: =F10 -> 6 | N10: {=ROUNDUP(IF(EQ(A10, ""),L10*INDEX(UncertaintyFactors!$C$2:$D$7, M10, 1), 0), 1)} -> 0 | O10: {=ROUNDUP(IF(EQ(A10, ""), L10*INDEX(UncertaintyFactors!$C$2:$D$7, M10, 2), 0), 1)} -> 0
B11: Secondary Header | D11: 0 | F11: 6 | G11: {=ROUNDUP(IF(EQ(A11, ""),E11*INDEX(UncertaintyFactors!$C$2:$D$7, F11, 1), 0), 1)} -> 0 | H11: {=ROUNDUP(IF(EQ(A11, ""), E11*INDEX(UncertaintyFactors!$C$2:$D$7, F11, 2), 0), 1)} -> 0 | L11: =E11-(E11*D11) -> 0 | M11: =F11 -> 6 | N11: {=ROUNDUP(IF(EQ(A11, ""),L11*INDEX(UncertaintyFactors!$C$2:$D$7, M11, 1), 0), 1)} -> 0 | O11: {=ROUNDUP(IF(EQ(A11, ""), L11*INDEX(UncertaintyFactors!$C$2:$D$7, M11, 2), 0), 1)} -> 0
B12: Hero Banner | D12: 0.05 | F12: 6 | G12: {=ROUNDUP(IF(EQ(A12, ""),E12*INDEX(UncertaintyFactors!$C$2:$D$7, F12, 1), 0), 1)} -> 0 | H12: {=ROUNDUP(IF(EQ(A12, ""), E12*INDEX(UncertaintyFactors!$C$2:$D$7, F12, 2), 0), 1)} -> 0 | L12: =E12-(E12*D12) -> 0 | M12: =F12 -> 6 | N12: {=ROUNDUP(IF(EQ(A12, ""),L12*INDEX(UncertaintyFactors!$C$2:$D$7, M12, 1), 0), 1)} -> 0 | O12: {=ROUNDUP(IF(EQ(A12, ""), L12*INDEX(UncertaintyFactors!$C$2:$D$7, M12, 2), 0), 1)} -> 0
B13: Hero Banner Carousel | D13: 0 | F13: 6 | G13: {=ROUNDUP(IF(EQ(A13, ""),E13*INDEX(UncertaintyFactors!$C$2:$D$7, F13, 1), 0), 1)} -> 0 | H13: {=ROUNDUP(IF(EQ(A13, ""), E13*INDEX(UncertaintyFactors!$C$2:$D$7, F13, 2), 0), 1)} -> 0 | L13: =E13-(E13*D13) -> 0 | M13: =F13 -> 6 | N13: {=ROUNDUP(IF(EQ(A13, ""),L13*INDEX(UncertaintyFactors!$C$2:$D$7, M13, 1), 0), 1)} -> 0 | O13: {=ROUNDUP(IF(EQ(A13, ""), L13*INDEX(UncertaintyFactors!$C$2:$D$7, M13, 2), 0), 1)} -> 0
